[2024-07-25T09:17:10.522+0000] {taskinstance.py:1159} INFO - Dependencies all met for dep_context=non-requeueable deps ti=<TaskInstance: simple_ids_ingest.get_id_from_json manual__2024-07-25T09:16:45.594968+00:00 [queued]>
[2024-07-25T09:17:10.938+0000] {taskinstance.py:1159} INFO - Dependencies all met for dep_context=requeueable deps ti=<TaskInstance: simple_ids_ingest.get_id_from_json manual__2024-07-25T09:16:45.594968+00:00 [queued]>
[2024-07-25T09:17:11.016+0000] {taskinstance.py:1361} INFO - Starting attempt 1 of 2
[2024-07-25T09:17:11.400+0000] {taskinstance.py:1382} INFO - Executing <Task(PythonOperator): get_id_from_json> on 2024-07-25 09:16:45.594968+00:00
[2024-07-25T09:17:11.603+0000] {standard_task_runner.py:57} INFO - Started process 539 to run task
[2024-07-25T09:17:11.761+0000] {standard_task_runner.py:84} INFO - Running: ['***', 'tasks', 'run', 'simple_ids_ingest', 'get_id_from_json', 'manual__2024-07-25T09:16:45.594968+00:00', '--job-id', '29', '--raw', '--subdir', 'DAGS_FOLDER/ids_ingest/ids_ingest_dag.py', '--cfg-path', '/tmp/tmpquy_agcx']
[2024-07-25T09:17:11.788+0000] {standard_task_runner.py:85} INFO - Job 29: Subtask get_id_from_json
[2024-07-25T09:17:12.413+0000] {task_command.py:416} INFO - Running <TaskInstance: simple_ids_ingest.get_id_from_json manual__2024-07-25T09:16:45.594968+00:00 [running]> on host c7799c7b21e5
[2024-07-25T09:17:13.125+0000] {taskinstance.py:1662} INFO - Exporting env vars: AIRFLOW_CTX_DAG_OWNER='Ajay' AIRFLOW_CTX_DAG_ID='simple_ids_ingest' AIRFLOW_CTX_TASK_ID='get_id_from_json' AIRFLOW_CTX_EXECUTION_DATE='2024-07-25T09:16:45.594968+00:00' AIRFLOW_CTX_TRY_NUMBER='1' AIRFLOW_CTX_DAG_RUN_ID='manual__2024-07-25T09:16:45.594968+00:00'
[2024-07-25T09:17:13.132+0000] {taskinstance.py:1937} ERROR - Task failed with exception
Traceback (most recent call last):
  File "/home/airflow/.local/lib/python3.8/site-packages/airflow/operators/python.py", line 192, in execute
    return_value = self.execute_callable()
  File "/home/airflow/.local/lib/python3.8/site-packages/airflow/operators/python.py", line 209, in execute_callable
    return self.python_callable(*self.op_args, **self.op_kwargs)
  File "/opt/airflow/dags/ids_ingest/ids_ingest_dag.py", line 18, in get_ids_from_json
    with open(filename_json, 'r') as f:
FileNotFoundError: [Errno 2] No such file or directory: '/opt/airflow/files_to_test/github_events.json'
[2024-07-25T09:17:13.182+0000] {taskinstance.py:1400} INFO - Marking task as UP_FOR_RETRY. dag_id=simple_ids_ingest, task_id=get_id_from_json, execution_date=20240725T091645, start_date=20240725T091710, end_date=20240725T091713
[2024-07-25T09:17:13.276+0000] {standard_task_runner.py:104} ERROR - Failed to execute job 29 for task get_id_from_json ([Errno 2] No such file or directory: '/opt/airflow/files_to_test/github_events.json'; 539)
[2024-07-25T09:17:13.372+0000] {local_task_job_runner.py:228} INFO - Task exited with return code 1
[2024-07-25T09:17:13.461+0000] {taskinstance.py:2778} INFO - 0 downstream tasks scheduled from follow-on schedule check
